Workbook

Sheet Read me
A1: SWGCG 301 - Phase 2 work distribution
A2: Deadline: Sat 5 Dec 2026 23:59 | Discussion: Sun 6 Dec 2026 16:00 | Proposal: Sat 28 Nov 2026 23:59
A3: Team: Mohamed (leader, the only one who submits on Moodle), Nour, Rahma, Hesham
A5: How to use
A6: 1. Go to the Tasks sheet. Only change the Status column (dropdown) and Notes. Do not edit Weight/Owner without telling the team.
A7: 2. Weight = effort points (1 trivial, 2 easy, 3 medium, 4 hard, 5 very hard). It is an estimate, not a grade.
A8: 3. A task counts as finished work only when Status = Done. The Workload sheet updates automatically.
A9: 4. If you swap a task with someone, change the Owner cell and tell the team. Totals recalculate.
A10: 5. To sort by ID low to high: click the filter arrow on the ID header and choose Sort Smallest to Largest (IDs are plain numbers 1, 2, 3... in section order). Sort by Owner, Status or Target date the same way.
A11: 6. Section 15 (Extras) are tasks added on top of the project document's requirements.
A12: 7. To share online: upload this file to Google Drive, open it with Google Sheets, then Share with the team (Editor).

Sheet Tasks
A1: ID | B1: Section | C1: Task | D1: Weight | E1: Owner | F1: Depends on | G1: Target date | H1: Status | I1: Notes
A2: 1 | B2: 0. Proposal | C2: Pick the game idea (everyone proposes, leader decides) | D2: 2 | E2: Mohamed | G2: 46334 | H2: Not started
A3: 2 | B3: 0. Proposal | C3: Write game name + description paragraph (how it is played, goal) | D3: 2 | E3: Nour | F3: 1 | G3: 46346 | H3: Not started
A4: 3 | B4: 0. Proposal | C4: Make the example image for the proposal | D4: 1 | E4: Rahma | F4: 1 | G4: 46346 | H4: Not started
A5: 4 | B5: 0. Proposal | C5: Add member names, IDs and team number | D5: 1 | E5: Mohamed | G5: 46352 | H5: Not started
A6: 5 | B6: 0. Proposal | C6: Submit proposal on Moodle (leader only) | D6: 1 | E6: Mohamed | F6: 2, 3, 4 | G6: 46354 | H6: Not started
A7: 6 | B7: 1. Project setup | C7: Restructure folders (engine/, assets/) | D7: 2 | E7: Mohamed | G7: 46329 | H7: Not started
A8: 7 | B8: 1. Project setup | C8: Update CMakeLists.txt (new sources, copy assets next to the exe) | D8: 2 | E8: Mohamed | F8: 6 | G8: 46329 | H8: Not started
A9: 8 | B9: 1. Project setup | C9: Add JSON parser (nlohmann/json) | D9: 1 | E9: Mohamed | G9: 46329 | H9: Not started
A10: 9 | B10: 1. Project setup | C10: Add stb_image | D10: 1 | E10: Hesham | G10: 46329 | H10: Not started
A11: 10 | B11: 1. Project setup | C11: Add tinyobjloader and GLM | D11: 1 | E11: Hesham | G11: 46329 | H11: Not started
A12: 11 | B12: 1. Project setup | C12: Decide what to do with the Phase 1 shapes | D12: 1 | E12: Mohamed | G12: 46329 | H12: Not started
A13: 12 | B13: 1. Project setup | C13: Update .gitignore and commit the project PDF | D13: 1 | E13: Mohamed | G13: 46329 | H13: Not started
A14: 13 | B14: 1. Project setup | C14: Agree on a branch strategy | D14: 1 | E14: Mohamed | G14: 46329 | H14: Not started
A15: 14 | B15: 2. Core ECS | C15: Component abstract base class | D15: 2 | E15: Mohamed | F15: 6 | G15: 46336 | H15: Not started
A16: 15 | B16: 2. Core ECS | C16: Entity class (name, parent, local transform, components) | D16: 3 | E16: Mohamed | F16: 14 | G16: 46336 | H16: Not started
A17: 16 | B17: 2. Core ECS | C17: Entity methods: addComponent, getComponent, getLocalToWorldMatrix | D17: 3 | E17: Mohamed | F17: 15 | G17: 46336 | H17: Not started
A18: 17 | B18: 2. Core ECS | C18: World class (add, delete, lookup) | D18: 2 | E18: Mohamed | F18: 15 | G18: 46336 | H18: Not started
A19: 18 | B19: 2. Core ECS | C19: Component factory/registry by type name | D19: 3 | E19: Mohamed | F19: 14 | G19: 46336 | H19: Not started
A20: 19 | B20: 2. Core ECS | C20: Deferred entity deletion | D20: 2 | E20: Mohamed | F20: 17 | G20: 46336 | H20: Not started
A21: 20 | B21: 3. Assets | C21: ShaderProgram wrapper (uniform setters + location cache) | D21: 3 | E21: Nour | F21: 7 | G21: 46340 | H21: Not started
A22: 21 | B22: 3. Assets | C22: Texture2D loader (stb_image, mipmaps) | D22: 3 | E22: Nour | F22: 9 | G22: 46340 | H22: Not started
A23: 22 | B23: 3. Assets | C23: Sampler (filtering, wrapping, anisotropy) | D23: 2 | E23: Nour | G23: 46340 | H23: Not started
A24: 23 | B24: 3. Assets | C24: Mesh (VBO, EBO, VAO, attributes) | D24: 4 | E24: Nour | G24: 46340 | H24: Not started
A25: 24 | B25: 3. Assets | C25: OBJ model loading | D25: 3 | E25: Nour | F25: 23, 10 | G25: 46340 | H25: Not started
A26: 25 | B26: 3. Assets | C26: Mesh deserialization from the scene file | D26: 2 | E26: Nour | F26: 23, 24 | G26: 46340 | H26: Not started
A27: 26 | B27: 3. Assets | C27: Deserialization functions for all assets | D27: 3 | E27: Nour | F27: 20-23 | G27: 46340 | H27: Not started
A28: 27 | B28: 3. Assets | C28: AssetLoader<T> template singleton (name -> asset map) | D28: 3 | E28: Nour | G28: 46340 | H28: Not started
A29: 28 | B29: 3. Assets | C29: Free GPU resources on exit / scene change | D29: 2 | E29: Nour | F29: 27 | G29: 46343 | H29: Not started
A30: 29 | B30: 4. Pipeline state & materials | C30: PipelineState struct (culling, depth, blending, color/depth masks) | D30: 3 | E30: Rahma | G30: 46340 | H30: Not started
A31: 30 | B31: 4. Pipeline state & materials | C31: PipelineState::setup() applies state to OpenGL | D31: 3 | E31: Rahma | F31: 29 | G31: 46340 | H31: Not started
A32: 31 | B32: 4. Pipeline state & materials | C32: PipelineState deserialization | D32: 3 | E32: Rahma | F32: 29 | G32: 46340 | H32: Not started
A33: 32 | B33: 4. Pipeline state & materials | C33: Material abstract base class | D33: 2 | E33: Rahma | F33: 30 | G33: 46340 | H33: Not started
A34: 33 | B34: 4. Pipeline state & materials | C34: TintedMaterial | D34: 2 | E34: Rahma | F34: 32, 20 | G34: 46340 | H34: Not started
A35: 34 | B35: 4. Pipeline state & materials | C35: TexturedMaterial | D35: 3 | E35: Rahma | F35: 32, 21, 22 | G35: 46340 | H35: Not started
A36: 35 | B36: 4. Pipeline state & materials | C36: Material asset loader with factory by type name | D36: 3 | E36: Rahma | F36: 27, 33, 34 | G36: 46343 | H36: Not started
A37: 36 | B37: 5. Components | C37: MeshRendererComponent | D37: 3 | E37: Hesham | F37: 14, 23, 32 | G37: 46340 | H37: Not started
A38: 37 | B38: 5. Components | C38: CameraComponent (type, FOV, ortho height, near/far) | D38: 3 | E38: Hesham | F38: 14 | G38: 46340 | H38: Not started
A39: 38 | B39: 5. Components | C39: Camera view / projection / view-projection matrices | D39: 3 | E39: Hesham | F39: 37 | G39: 46340 | H39: Not started
A40: 39 | B40: 5. Components | C40: FreeCameraControllerComponent (parameters) | D40: 4 | E40: Hesham | F40: 37 | G40: 46340 | H40: Not started
...

Sheet Workload
A1: Workload per member
A3: Member | B3: Total points | C3: Share | D3: Tasks | E3: Done points | F3: Done % | G3: Remaining points | H3: Core points (sections 0-14) | I3: Extra points (section 15)
A4: Mohamed | B4: =SUMIFS(Tasks!$D$2:$D$300,Tasks!$E$2:$E$300,A4) -> 56 | C4: =IFERROR(B4/$B$8,0) -> 0.26046512 | D4: =COUNTIFS(Tasks!$E$2:$E$300,A4) -> 28 | E4: =SUMIFS(Tasks!$D$2:$D$300,Tasks!$E$2:$E$300,A4,Tasks!$H$2:$H$300,"Done") -> 0 | F4: =IFERROR(E4/B4,0) -> 0 | G4: =B4-E4 -> 56 | H4: =B4-I4 -> 53 | I4: =SUMIFS(Tasks!$D$2:$D$300,Tasks!$E$2:$E$300,A4,Tasks!$B$2:$B$300,"15. *") -> 3
A5: Nour | B5: =SUMIFS(Tasks!$D$2:$D$300,Tasks!$E$2:$E$300,A5) -> 53 | C5: =IFERROR(B5/$B$8,0) -> 0.24651163 | D5: =COUNTIFS(Tasks!$E$2:$E$300,A5) -> 23 | E5: =SUMIFS(Tasks!$D$2:$D$300,Tasks!$E$2:$E$300,A5,Tasks!$H$2:$H$300,"Done") -> 0 | F5: =IFERROR(E5/B5,0) -> 0 | G5: =B5-E5 -> 53 | H5: =B5-I5 -> 51 | I5: =SUMIFS(Tasks!$D$2:$D$300,Tasks!$E$2:$E$300,A5,Tasks!$B$2:$B$300,"15. *") -> 2
A6: Rahma | B6: =SUMIFS(Tasks!$D$2:$D$300,Tasks!$E$2:$E$300,A6) -> 53 | C6: =IFERROR(B6/$B$8,0) -> 0.24651163 | D6: =COUNTIFS(Tasks!$E$2:$E$300,A6) -> 24 | E6: =SUMIFS(Tasks!$D$2:$D$300,Tasks!$E$2:$E$300,A6,Tasks!$H$2:$H$300,"Done") -> 0 | F6: =IFERROR(E6/B6,0) -> 0 | G6: =B6-E6 -> 53 | H6: =B6-I6 -> 49 | I6: =SUMIFS(Tasks!$D$2:$D$300,Tasks!$E$2:$E$300,A6,Tasks!$B$2:$B$300,"15. *") -> 4
A7: Hesham | B7: =SUMIFS(Tasks!$D$2:$D$300,Tasks!$E$2:$E$300,A7) -> 53 | C7: =IFERROR(B7/$B$8,0) -> 0.24651163 | D7: =COUNTIFS(Tasks!$E$2:$E$300,A7) -> 26 | E7: =SUMIFS(Tasks!$D$2:$D$300,Tasks!$E$2:$E$300,A7,Tasks!$H$2:$H$300,"Done") -> 0 | F7: =IFERROR(E7/B7,0) -> 0 | G7: =B7-E7 -> 53 | H7: =B7-I7 -> 51 | I7: =SUMIFS(Tasks!$D$2:$D$300,Tasks!$E$2:$E$300,A7,Tasks!$B$2:$B$300,"15. *") -> 2
A8: Team | B8: =SUM(B4:B7) -> 215 | C8: =SUM(C4:C7) -> 1 | D8: =SUM(D4:D7) -> 101 | E8: =SUM(E4:E7) -> 0 | F8: =IFERROR(E8/B8,0) -> 0 | G8: =SUM(G4:G7) -> 215 | H8: =SUM(H4:H7) -> 204 | I8: =SUM(I4:I7) -> 11
A11: Points per section and member
A12: Section | B12: Mohamed | C12: Nour | D12: Rahma | E12: Hesham | F12: Section total
A13: 0. Proposal | B13: =SUMIFS(Tasks!$D$2:$D$300,Tasks!$B$2:$B$300,$A13,Tasks!$E$2:$E$300,B$12) -> 4 | C13: =SUMIFS(Tasks!$D$2:$D$300,Tasks!$B$2:$B$300,$A13,Tasks!$E$2:$E$300,C$12) -> 2 | D13: =SUMIFS(Tasks!$D$2:$D$300,Tasks!$B$2:$B$300,$A13,Tasks!$E$2:$E$300,D$12) -> 1 | E13: =SUMIFS(Tasks!$D$2:$D$300,Tasks!$B$2:$B$300,$A13,Tasks!$E$2:$E$300,E$12) -> 0 | F13: =SUM(B13:E13) -> 7
A14: 1. Project setup | B14: =SUMIFS(Tasks!$D$2:$D$300,Tasks!$B$2:$B$300,$A14,Tasks!$E$2:$E$300,B$12) -> 8 | C14: =SUMIFS(Tasks!$D$2:$D$300,Tasks!$B$2:$B$300,$A14,Tasks!$E$2:$E$300,C$12) -> 0 | D14: =SUMIFS(Tasks!$D$2:$D$300,Tasks!$B$2:$B$300,$A14,Tasks!$E$2:$E$300,D$12) -> 0 | E14: =SUMIFS(Tasks!$D$2:$D$300,Tasks!$B$2:$B$300,$A14,Tasks!$E$2:$E$300,E$12) -> 2 | F14: =SUM(B14:E14) -> 10
A15: 2. Core ECS | B15: =SUMIFS(Tasks!$D$2:$D$300,Tasks!$B$2:$B$300,$A15,Tasks!$E$2:$E$300,B$12) -> 15 | C15: =SUMIFS(Tasks!$D$2:$D$300,Tasks!$B$2:$B$300,$A15,Tasks!$E$2:$E$300,C$12) -> 0 | D15: =SUMIFS(Tasks!$D$2:$D$300,Tasks!$B$2:$B$300,$A15,Tasks!$E$2:$E$300,D$12) -> 0 | E15: =SUMIFS(Tasks!$D$2:$D$300,Tasks!$B$2:$B$300,$A15,Tasks!$E$2:$E$300,E$12) -> 0 | F15: =SUM(B15:E15) -> 15
A16: 3. Assets | B16: =SUMIFS(Tasks!$D$2:$D$300,Tasks!$B$2:$B$300,$A16,Tasks!$E$2:$E$300,B$12) -> 0 | C16: =SUMIFS(Tasks!$D$2:$D$300,Tasks!$B$2:$B$300,$A16,Tasks!$E$2:$E$300,C$12) -> 25 | D16: =SUMIFS(Tasks!$D$2:$D$300,Tasks!$B$2:$B$300,$A16,Tasks!$E$2:$E$300,D$12) -> 0 | E16: =SUMIFS(Tasks!$D$2:$D$300,Tasks!$B$2:$B$300,$A16,Tasks!$E$2:$E$300,E$12) -> 0 | F16: =SUM(B16:E16) -> 25
A17: 4. Pipeline state & materials | B17: =SUMIFS(Tasks!$D$2:$D$300,Tasks!$B$2:$B$300,$A17,Tasks!$E$2:$E$300,B$12) -> 0 | C17: =SUMIFS(Tasks!$D$2:$D$300,Tasks!$B$2:$B$300,$A17,Tasks!$E$2:$E$300,C$12) -> 0 | D17: =SUMIFS(Tasks!$D$2:$D$300,Tasks!$B$2:$B$300,$A17,Tasks!$E$2:$E$300,D$12) -> 19 | E17: =SUMIFS(Tasks!$D$2:$D$300,Tasks!$B$2:$B$300,$A17,Tasks!$E$2:$E$300,E$12) -> 0 | F17: =SUM(B17:E17) -> 19
A18: 5. Components | B18: =SUMIFS(Tasks!$D$2:$D$300,Tasks!$B$2:$B$300,$A18,Tasks!$E$2:$E$300,B$12) -> 0 | C18: =SUMIFS(Tasks!$D$2:$D$300,Tasks!$B$2:$B$300,$A18,Tasks!$E$2:$E$300,C$12) -> 0 | D18: =SUMIFS(Tasks!$D$2:$D$300,Tasks!$B$2:$B$300,$A18,Tasks!$E$2:$E$300,D$12) -> 0 | E18: =SUMIFS(Tasks!$D$2:$D$300,Tasks!$B$2:$B$300,$A18,Tasks!$E$2:$E$300,E$12) -> 15 | F18: =SUM(B18:E18) -> 15
A19: 6. Forward renderer | B19: =SUMIFS(Tasks!$D$2:$D$300,Tasks!$B$2:$B$300,$A19,Tasks!$E$2:$E$300,B$12) -> 0 | C19: =SUMIFS(Tasks!$D$2:$D$300,Tasks!$B$2:$B$300,$A19,Tasks!$E$2:$E$300,C$12) -> 0 | D19: =SUMIFS(Tasks!$D$2:$D$300,Tasks!$B$2:$B$300,$A19,Tasks!$E$2:$E$300,D$12) -> 18 | E19: =SUMIFS(Tasks!$D$2:$D$300,Tasks!$B$2:$B$300,$A19,Tasks!$E$2:$E$300,E$12) -> 0 | F19: =SUM(B19:E19) -> 18
A20: 7. Sky | B20: =SUMIFS(Tasks!$D$2:$D$300,Tasks!$B$2:$B$300,$A20,Tasks!$E$2:$E$300,B$12) -> 0 | C20: =SUMIFS(Tasks!$D$2:$D$300,Tasks!$B$2:$B$300,$A20,Tasks!$E$2:$E$300,C$12) -> 11 | D20: =SUMIFS(Tasks!$D$2:$D$300,Tasks!$B$2:$B$300,$A20,Tasks!$E$2:$E$300,D$12) -> 0 | E20: =SUMIFS(Tasks!$D$2:$D$300,Tasks!$B$2:$B$300,$A20,Tasks!$E$2:$E$300,E$12) -> 0 | F20: =SUM(B20:E20) -> 11
A21: 8. Post-processing | B21: =SUMIFS(Tasks!$D$2:$D$300,Tasks!$B$2:$B$300,$A21,Tasks!$E$2:$E$300,B$12) -> 0 | C21: =SUMIFS(Tasks!$D$2:$D$300,Tasks!$B$2:$B$300,$A21,Tasks!$E$2:$E$300,C$12) -> 0 | D21: =SUMIFS(Tasks!$D$2:$D$300,Tasks!$B$2:$B$300,$A21,Tasks!$E$2:$E$300,D$12) -> 0 | E21: =SUMIFS(Tasks!$D$2:$D$300,Tasks!$B$2:$B$300,$A21,Tasks!$E$2:$E$300,E$12) -> 16 | F21: =SUM(B21:E21) -> 16
A22: 9. Free camera system | B22: =SUMIFS(Tasks!$D$2:$D$300,Tasks!$B$2:$B$300,$A22,Tasks!$E$2:$E$300,B$12) -> 0 | C22: =SUMIFS(Tasks!$D$2:$D$300,Tasks!$B$2:$B$300,$A22,Tasks!$E$2:$E$300,C$12) -> 0 | D22: =SUMIFS(Tasks!$D$2:$D$300,Tasks!$B$2:$B$300,$A22,Tasks!$E$2:$E$300,D$12) -> 0 | E22: =SUMIFS(Tasks!$D$2:$D$300,Tasks!$B$2:$B$300,$A22,Tasks!$E$2:$E$300,E$12) -> 7 | F22: =SUM(B22:E22) -> 7
A23: 10. Application | B23: =SUMIFS(Tasks!$D$2:$D$300,Tasks!$B$2:$B$300,$A23,Tasks!$E$2:$E$300,B$12) -> 8 | C23: =SUMIFS(Tasks!$D$2:$D$300,Tasks!$B$2:$B$300,$A23,Tasks!$E$2:$E$300,C$12) -> 0 | D23: =SUMIFS(Tasks!$D$2:$D$300,Tasks!$B$2:$B$300,$A23,Tasks!$E$2:$E$300,D$12) -> 0 | E23: =SUMIFS(Tasks!$D$2:$D$300,Tasks!$B$2:$B$300,$A23,Tasks!$E$2:$E$300,E$12) -> 0 | F23: =SUM(B23:E23) -> 8
A24: 11. Scene file & deserialization | B24: =SUMIFS(Tasks!$D$2:$D$300,Tasks!$B$2:$B$300,$A24,Tasks!$E$2:$E$300,B$12) -> 12 | C24: =SUMIFS(Tasks!$D$2:$D$300,Tasks!$B$2:$B$300,$A24,Tasks!$E$2:$E$300,C$12) -> 3 | D24: =SUMIFS(Tasks!$D$2:$D$300,Tasks!$B$2:$B$300,$A24,Tasks!$E$2:$E$300,D$12) -> 0 | E24: =SUMIFS(Tasks!$D$2:$D$300,Tasks!$B$2:$B$300,$A24,Tasks!$E$2:$E$300,E$12) -> 0 | F24: =SUM(B24:E24) -> 15
... A28: 15. Extras (added) | B28: =SUMIFS(Tasks!$D$2:$D$300,Tasks!$B$2:$B$300,$A28,Tasks!$E$2:$E$300,B$12) -> 3 | C28: =SUMIFS(Tasks!$D$2:$D$300,Tasks!$B$2:$B$300,$A28,Tasks!$E$2:$E$300,C$12) -> 2 | D28: =SUMIFS(Tasks!$D$2:$D$300,Tasks!$B$2:$B$300,$A28,Tasks!$E$2:$E$300,D$12) -> 4 | E28: =SUMIFS(Tasks!$D$2:$D$300,Tasks!$B$2:$B$300,$A28,Tasks!$E$2:$E$300,E$12) -> 2 | F28: =SUM(B28:E28) -> 11
A29: Total | B29: =SUM(B13:B28) -> 56 | C29: =SUM(C13:C28) -> 53 | D29: =SUM(D13:D28) -> 53 | E29: =SUM(E13:E28) -> 53 | F29: =SUM(F13:F28) -> 215

Sheet Milestones
A1: Date | B1: Milestone | C1: Who
A2: 46327 | B2: Kickoff done: interfaces agreed, collaborators added | C2: Mohamed
A3: 46329 | B3: Project restructured, libraries added, CMake builds | C3: Mohamed, Hesham
A4: 46336 | B4: ECS core compiles; assets and models gathered | C4: Mohamed, Rahma
A5: 46340 | B5: Assets, materials, pipeline state and components code-complete | C5: Nour, Rahma, Hesham
A6: 46346 | B6: Forward renderer + sky + scene loading draw a scene from JSON | C6: Rahma, Nour, Mohamed
A7: 46350 | B7: Post-processing and scene-configured renderer working | C7: Hesham, Mohamed
A8: 46354 | B8: Proposal submitted on Moodle | C8: Mohamed
A9: 46356 | B9: All test scenes working | C9: Hesham, Rahma
A10: 46358 | B10: Testing finished, bugs fixed | C10: Everyone
A11: 46359 | B11: Code freeze: comments, README, clean-clone build | C11: Everyone
A12: 46360 | B12: Zip and submit (one-day buffer) | C12: Mohamed
A13: 46361 | B13: Phase 2 deadline 23:59 | C13: Mohamed
A14: 46362 | B14: Phase 2 discussion 16:00 | C14: Everyone
